<?xml version="1.0" ?>
<!-- =================================================================================== -->
<!-- |    This document was autogenerated by xacro from robot.xacro                    | -->
<!-- |    EDITING THIS FILE BY HAND IS NOT RECOMMENDED                                 | -->
<!-- =================================================================================== -->
<robot name="arx_lift2s">
  <link name="base_link">
    <inertial>
      <origin xyz="-0.010039 0.0013761 0.04956"/>
      <mass value="21.045"/>
      <inertia ixx="1.70029164" ixy="-0.00073232" ixz="-0.03255532" iyy="1.70804910" iyz="-0.00688370" izz="0.97173287"/>
    </inertial>
    <visual>
      <geometry>
        <mesh filename="file:///home/shimanliang/ros2_ws/install/arx_lift2s_description/share/arx_lift2s_description/meshes/base_link.glb"/>
      </geometry>
    </visual>
    <collision>
      <geometry>
        <mesh filename="file:///home/shimanliang/ros2_ws/install/arx_lift2s_description/share/arx_lift2s_description/meshes/base_link.glb"/>
      </geometry>
    </collision>
  </link>
  <link name="lift_link">
    <inertial>
      <origin xyz="-0.053315 -0.00061422 -0.0086454"/>
      <mass value="14.181"/>
      <inertia ixx="0.32744849" ixy="-0.00306617" ixz="0.05920163" iyy="0.36541112" iyz="0.00117932" izz="0.49616592"/>
    </inertial>
    <visual>
      <geometry>
        <mesh filename="file:///home/shimanliang/ros2_ws/install/arx_lift2s_description/share/arx_lift2s_description/meshes/body4.glb"/>
      </geometry>
    </visual>
    <collision>
      <geometry>
        <mesh filename="file:///home/shimanliang/ros2_ws/install/arx_lift2s_description/share/arx_lift2s_description/meshes/body4.glb"/>
      </geometry>
    </collision>
  </link>
  <joint name="lift_joint" type="prismatic">
    <origin xyz="0.094118 0.0010067 0.27"/>
    <parent link="base_link"/>
    <child link="lift_link"/>
    <axis xyz="0 0 1"/>
    <limit effort="400" lower="0" upper="0.46" velocity="0.15"/>
  </joint>
  <!-- 轮子链接 -->
  <link name="wheel_1">
    <inertial>
      <origin xyz="0.035966 2.8161E-06 7.9768E-09"/>
      <mass value="0.5746"/>
      <inertia ixx="0.00142306" ixy="0.00000000" ixz="0.00000000" iyy="0.00084449" iyz="0.00000002" izz="0.00084474"/>
    </inertial>
    <visual>
      <geometry>
        <mesh filename="file:///home/shimanliang/ros2_ws/install/arx_lift2s_description/share/arx_lift2s_description/meshes/wheel_1.glb"/>
      </geometry>
    </visual>
    <collision>
      <geometry>
        <mesh filename="file:///home/shimanliang/ros2_ws/install/arx_lift2s_description/share/arx_lift2s_description/meshes/wheel_1.glb"/>
      </geometry>
    </collision>
  </link>
  <!-- 轮子链接 -->
  <link name="wheel_2">
    <inertial>
      <origin xyz="0.035966 2.8161E-06 7.9768E-09"/>
      <mass value="0.5746"/>
      <inertia ixx="0.00142306" ixy="0.00000000" ixz="0.00000000" iyy="0.00084449" iyz="0.00000002" izz="0.00084474"/>
    </inertial>
    <visual>
      <geometry>
        <mesh filename="file:///home/shimanliang/ros2_ws/install/arx_lift2s_description/share/arx_lift2s_description/meshes/wheel_2.glb"/>
      </geometry>
    </visual>
    <collision>
      <geometry>
        <mesh filename="file:///home/shimanliang/ros2_ws/install/arx_lift2s_description/share/arx_lift2s_description/meshes/wheel_2.glb"/>
      </geometry>
    </collision>
  </link>
  <!-- 轮子链接 -->
  <link name="wheel_3">
    <inertial>
      <origin xyz="0.035966 2.8161E-06 7.9768E-09"/>
      <mass value="0.5746"/>
      <inertia ixx="0.00142306" ixy="0.00000000" ixz="0.00000000" iyy="0.00084449" iyz="0.00000002" izz="0.00084474"/>
    </inertial>
    <visual>
      <geometry>
        <mesh filename="file:///home/shimanliang/ros2_ws/install/arx_lift2s_description/share/arx_lift2s_description/meshes/wheel_3.glb"/>
      </geometry>
    </visual>
    <collision>
      <geometry>
        <mesh filename="file:///home/shimanliang/ros2_ws/install/arx_lift2s_description/share/arx_lift2s_description/meshes/wheel_3.glb"/>
      </geometry>
    </collision>
  </link>
  <!-- 轮子关节定义 -->
  <joint name="wheel1_joint" type="fixed">
    <origin rpy="0.0 0.0 1.0472" xyz="0.15361 0.29246 -0.093"/>
    <parent link="base_link"/>
    <child link="wheel_1"/>
  </joint>
  <joint name="wheel2_joint" type="fixed">
    <origin rpy="0.0 0.0 -1.0472" xyz="0.15361 -0.29245 -0.093"/>
    <parent link="base_link"/>
    <child link="wheel_2"/>
  </joint>
  <joint name="wheel3_joint" type="fixed">
    <origin rpy="0.0 0.0 0" xyz="-0.35293 0 -0.093"/>
    <parent link="base_link"/>
    <child link="wheel_3"/>
  </joint>
  <link name="left_base_link">
    <inertial>
      <origin xyz="-3.0001E-05 3.0589E-05 0.027324"/>
      <mass value="0.43995"/>
      <inertia ixx="0.00017" ixy="0.00000" ixz="0.00000" iyy="0.00017" iyz="0.00000" izz="0.00016"/>
    </inertial>
    <visual>
      <geometry>
        <mesh filename="file:///home/shimanliang/ros2_ws/install/arx5_description/share/arx5_description/meshes/x5/base_link.obj"/>
      </geometry>
    </visual>
    <collision>
      <geometry>
        <mesh filename="file:///home/shimanliang/ros2_ws/install/arx5_description/share/arx5_description/meshes/x5/base_link.obj"/>
      </geometry>
    </collision>
  </link>
  <link name="left_link1">
    <inertial>
      <origin xyz="0.0054231 -0.0080289 0.017086"/>
      <mass value="0.066982"/>
      <inertia ixx="0.00008" ixy="0.00000" ixz="0.00001" iyy="0.00003" iyz="0.00000" izz="0.00008"/>
    </inertial>
    <visual>
      <geometry>
        <mesh filename="file:///home/shimanliang/ros2_ws/install/arx5_description/share/arx5_description/meshes/x5/link1.obj"/>
      </geometry>
    </visual>
    <collision>
      <geometry>
        <mesh filename="file:///home/shimanliang/ros2_ws/install/arx5_description/share/arx5_description/meshes/x5/link1.obj"/>
      </geometry>
    </collision>
  </link>
  <joint name="left_joint1" type="revolute">
    <origin xyz="0 0 0.0605"/>
    <parent link="left_base_link"/>
    <child link="left_link1"/>
    <axis xyz="0 0 1"/>
    <limit effort="100" lower="-2.87" upper="3.14" velocity="5"/>
  </joint>
  <link name="left_link2">
    <inertial>
      <origin xyz="-0.13237 0.0020852 0.00010549"/>
      <mass value="1.0795"/>
      <inertia ixx="0.00051" ixy="0.00001" ixz="-0.00004" iyy="0.01599" iyz="0.00000" izz="0.01605"/>
    </inertial>
    <visual>
      <geometry>
        <mesh filename="file:///home/shimanliang/ros2_ws/install/arx5_description/share/arx5_description/meshes/x5/link2.obj"/>
      </geometry>
    </visual>
    <collision>
      <geometry>
        <mesh filename="file:///home/shimanliang/ros2_ws/install/arx5_description/share/arx5_description/meshes/x5/link2.obj"/>
      </geometry>
    </collision>
  </link>
  <joint name="left_joint2" type="revolute">
    <origin xyz="0.02 0 0.04"/>
    <parent link="left_link1"/>
    <child link="left_link2"/>
    <axis xyz="0 1 0"/>
    <limit effort="100" lower="0" upper="3.66" velocity="5"/>
  </joint>
  <link name="left_link3">
    <inertial>
      <origin xyz="0.18531 0.00068376 -0.051638"/>
      <mass value="0.54534"/>
      <inertia ixx="0.00036" ixy="-0.00003" ixz="-0.00039" iyy="0.00423" iyz="0.00001" izz="0.00420"/>
    </inertial>
    <visual>
      <geometry>
        <mesh filename="file:///home/shimanliang/ros2_ws/install/arx5_description/share/arx5_description/meshes/x5/link3.obj"/>
      </geometry>
    </visual>
    <collision>
      <geometry>
        <mesh filename="file:///home/shimanliang/ros2_ws/install/arx5_description/share/arx5_description/meshes/x5/link3.obj"/>
      </geometry>
    </collision>
  </link>
  <joint name="left_joint3" type="revolute">
    <origin rpy="3.1416 0 0" xyz="-0.264 0 0"/>
    <parent link="left_link2"/>
    <child link="left_link3"/>
    <axis xyz="0 1 0"/>
    <limit effort="100" lower="0" upper="3.14" velocity="5"/>
  </joint>
  <link name="left_link4">
    <inertial>
      <origin xyz="0.040231 0.0044807 -0.035335"/>
      <mass value="0.11714"/>
      <inertia ixx="0.00019" ixy="-0.00002" ixz="-0.00009" iyy="0.00023" iyz="0.00002" izz="0.00014"/>
    </inertial>
    <visual>
      <geometry>
        <mesh filename="file:///home/shimanliang/ros2_ws/install/arx5_description/share/arx5_description/meshes/x5/link4.obj"/>
      </geometry>
    </visual>
    <collision>
      <geometry>
        <mesh filename="file:///home/shimanliang/ros2_ws/install/arx5_description/share/arx5_description/meshes/x5/link4.obj"/>
      </geometry>
    </collision>
  </link>
  <joint name="left_joint4" type="revolute">
    <origin xyz="0.245 0 -0.056"/>
    <parent link="left_link3"/>
    <child link="left_link4"/>
    <axis xyz="0 1 0"/>
    <limit effort="100" lower="-1.57" upper="1.57" velocity="5"/>
  </joint>
  <link name="left_link5">
    <inertial>
      <origin xyz="0.003612 -1.5455E-05 0.055214"/>
      <mass value="0.63488"/>
      <inertia ixx="0.00083" ixy="0.00000" ixz="0.00007" iyy="0.00082" iyz="0.00000" izz="0.00026"/>
    </inertial>
    <visual>
      <origin xyz="0.0037 0 0"/>
      <geometry>
        <mesh filename="file:///home/shimanliang/ros2_ws/install/arx5_description/share/arx5_description/meshes/x5/link5.obj"/>
      </geometry>
    </visual>
    <collision>
      <geometry>
        <mesh filename="file:///home/shimanliang/ros2_ws/install/arx5_description/share/arx5_description/meshes/x5/link5.obj"/>
      </geometry>
    </collision>
  </link>
  <joint name="left_joint5" type="revolute">
    <origin xyz="0.06775 0.0005 -0.0865"/>
    <parent link="left_link4"/>
    <child link="left_link5"/>
    <axis xyz="0 0 1"/>
    <limit effort="100" lower="-1.57" upper="1.57" velocity="5"/>
  </joint>
  <link name="left_link6">
    <inertial>
      <origin xyz="0.041697 2.4368E-05 0.00014464"/>
      <mass value="0.44089"/>
      <inertia ixx="0.00038" ixy="0.00000" ixz="0.00000" iyy="0.00028" iyz="0.00000" izz="0.00050"/>
    </inertial>
    <visual>
      <geometry>
        <mesh filename="file:///home/shimanliang/ros2_ws/install/arx5_description/share/arx5_description/meshes/x5/link6.obj"/>
      </geometry>
    </visual>
    <collision>
      <geometry>
        <mesh filename="file:///home/shimanliang/ros2_ws/install/arx5_description/share/arx5_description/meshes/x5/link6.obj"/>
      </geometry>
    </collision>
  </link>
  <joint name="left_joint6" type="revolute">
    <origin rpy="-3.1416 0 0" xyz="0.02895 0 0.0865"/>
    <parent link="left_link5"/>
    <child link="left_link6"/>
    <axis xyz="1 0 0"/>
    <limit effort="100" lower="-1.57" upper="1.57" velocity="5"/>
  </joint>
  <link name="left_link7">
    <inertial>
      <origin xyz="-0.00035522 -0.007827 -0.0029883"/>
      <mass value="0.064798"/>
      <inertia ixx="0.00002" ixy="0.00000" ixz="0.00000" iyy="0.00003" iyz="0.00000" izz="0.00003"/>
    </inertial>
    <visual>
      <geometry>
        <mesh filename="file:///home/shimanliang/ros2_ws/install/arx5_description/share/arx5_description/meshes/x5/link7.obj"/>
      </geometry>
    </visual>
    <collision>
      <geometry>
        <mesh filename="file:///home/shimanliang/ros2_ws/install/arx5_description/share/arx5_description/meshes/x5/link7.obj"/>
      </geometry>
    </collision>
  </link>
  <joint name="left_gripper_joint" type="prismatic">
    <origin xyz="0.08657 0.024896 -0.0002436"/>
    <parent link="left_link6"/>
    <child link="left_link7"/>
    <axis xyz="0 1 0"/>
    <limit effort="100" lower="0" upper="0.044" velocity="5"/>
  </joint>
  <link name="left_link8">
    <inertial>
      <origin xyz="-0.00035522 0.0078277 0.0024201"/>
      <mass value="0.064798"/>
      <inertia ixx="0.00002" ixy="0.00000" ixz="0.00000" iyy="0.00003" iyz="0.00000" izz="0.00003"/>
    </inertial>
    <visual>
      <geometry>
        <mesh filename="file:///home/shimanliang/ros2_ws/install/arx5_description/share/arx5_description/meshes/x5/link8.obj"/>
      </geometry>
    </visual>
    <collision>
      <geometry>
        <mesh filename="file:///home/shimanliang/ros2_ws/install/arx5_description/share/arx5_description/meshes/x5/link8.obj"/>
      </geometry>
    </collision>
  </link>
  <joint name="left_joint8" type="prismatic">
    <origin xyz="0.08657 -0.0249 -0.00024366"/>
    <parent link="left_link6"/>
    <child link="left_link8"/>
    <axis xyz="0 -1 0"/>
    <limit effort="100" lower="0" upper="0.044" velocity="5"/>
    <mimic joint="left_gripper_joint" multiplier="1" offset="0"/>
  </joint>
  <link name="left_gripper_center"/>
  <joint name="left_gripper_center_fixed" type="fixed">
    <parent link="left_link6"/>
    <child link="left_gripper_center"/>
    <origin xyz="0.145 0 0"/>
  </joint>
  <link name="left_left_pad"/>
  <joint name="left_left_pad_joint" type="fixed">
    <parent link="left_link7"/>
    <child link="left_left_pad"/>
    <origin xyz="0.05843 -0.0249 0"/>
  </joint>
  <link name="left_right_pad"/>
  <joint name="left_right_pad_joint" type="fixed">
    <parent link="left_link8"/>
    <child link="left_right_pad"/>
    <origin xyz="0.05843 0.0249 0"/>
  </joint>
  <link name="left_camera_support">
    <visual>
      <geometry>
        <mesh filename="file:///home/shimanliang/ros2_ws/install/arx5_description/share/arx5_description/meshes/camera_stand/stand_d405.obj"/>
      </geometry>
    </visual>
  </link>
  <joint name="left_camera_support_fixed" type="fixed">
    <parent link="left_link6"/>
    <child link="left_camera_support"/>
    <origin xyz="0.045 0 0.021"/>
  </joint>
  <link name="left_camera">
    <visual>
      <geometry>
        <mesh filename="file:///home/shimanliang/ros2_ws/install/sensor_models/share/sensor_models/meshes/d405/d405.obj"/>
      </geometry>
    </visual>
  </link>
  <joint name="left_camera_fixed" type="fixed">
    <origin rpy="0 0.523 0" xyz="0.0385 0 0.0475"/>
    <parent link="left_camera_support"/>
    <child link="left_camera"/>
  </joint>
  <link name="right_base_link">
    <inertial>
      <origin xyz="-3.0001E-05 3.0589E-05 0.027324"/>
      <mass value="0.43995"/>
      <inertia ixx="0.00017" ixy="0.00000" ixz="0.00000" iyy="0.00017" iyz="0.00000" izz="0.00016"/>
    </inertial>
    <visual>
      <geometry>
        <mesh filename="file:///home/shimanliang/ros2_ws/install/arx5_description/share/arx5_description/meshes/x5/base_link.obj"/>
      </geometry>
    </visual>
    <collision>
      <geometry>
        <mesh filename="file:///home/shimanliang/ros2_ws/install/arx5_description/share/arx5_description/meshes/x5/base_link.obj"/>
      </geometry>
    </collision>
  </link>
  <link name="right_link1">
    <inertial>
      <origin xyz="0.0054231 -0.0080289 0.017086"/>
      <mass value="0.066982"/>
      <inertia ixx="0.00008" ixy="0.00000" ixz="0.00001" iyy="0.00003" iyz="0.00000" izz="0.00008"/>
    </inertial>
    <visual>
      <geometry>
        <mesh filename="file:///home/shimanliang/ros2_ws/install/arx5_description/share/arx5_description/meshes/x5/link1.obj"/>
      </geometry>
    </visual>
    <collision>
      <geometry>
        <mesh filename="file:///home/shimanliang/ros2_ws/install/arx5_description/share/arx5_description/meshes/x5/link1.obj"/>
      </geometry>
    </collision>
  </link>
  <joint name="right_joint1" type="revolute">
    <origin xyz="0 0 0.0605"/>
    <parent link="right_base_link"/>
    <child link="right_link1"/>
    <axis xyz="0 0 1"/>
    <limit effort="100" lower="-2.87" upper="3.14" velocity="5"/>
  </joint>
  <link name="right_link2">
    <inertial>
      <origin xyz="-0.13237 0.0020852 0.00010549"/>
      <mass value="1.0795"/>
      <inertia ixx="0.00051" ixy="0.00001" ixz="-0.00004" iyy="0.01599" iyz="0.00000" izz="0.01605"/>
    </inertial>
    <visual>
      <geometry>
        <mesh filename="file:///home/shimanliang/ros2_ws/install/arx5_description/share/arx5_description/meshes/x5/link2.obj"/>
      </geometry>
    </visual>
    <collision>
      <geometry>
        <mesh filename="file:///home/shimanliang/ros2_ws/install/arx5_description/share/arx5_description/meshes/x5/link2.obj"/>
      </geometry>
    </collision>
  </link>
  <joint name="right_joint2" type="revolute">
    <origin xyz="0.02 0 0.04"/>
    <parent link="right_link1"/>
    <child link="right_link2"/>
    <axis xyz="0 1 0"/>
    <limit effort="100" lower="0" upper="3.66" velocity="5"/>
  </joint>
  <link name="right_link3">
    <inertial>
      <origin xyz="0.18531 0.00068376 -0.051638"/>
      <mass value="0.54534"/>
      <inertia ixx="0.00036" ixy="-0.00003" ixz="-0.00039" iyy="0.00423" iyz="0.00001" izz="0.00420"/>
    </inertial>
    <visual>
      <geometry>
        <mesh filename="file:///home/shimanliang/ros2_ws/install/arx5_description/share/arx5_description/meshes/x5/link3.obj"/>
      </geometry>
    </visual>
    <collision>
      <geometry>
        <mesh filename="file:///home/shimanliang/ros2_ws/install/arx5_description/share/arx5_description/meshes/x5/link3.obj"/>
      </geometry>
    </collision>
  </link>
  <joint name="right_joint3" type="revolute">
    <origin rpy="3.1416 0 0" xyz="-0.264 0 0"/>
    <parent link="right_link2"/>
    <child link="right_link3"/>
    <axis xyz="0 1 0"/>
    <limit effort="100" lower="0" upper="3.14" velocity="5"/>
  </joint>
  <link name="right_link4">
    <inertial>
      <origin xyz="0.040231 0.0044807 -0.035335"/>
      <mass value="0.11714"/>
      <inertia ixx="0.00019" ixy="-0.00002" ixz="-0.00009" iyy="0.00023" iyz="0.00002" izz="0.00014"/>
    </inertial>
    <visual>
      <geometry>
        <mesh filename="file:///home/shimanliang/ros2_ws/install/arx5_description/share/arx5_description/meshes/x5/link4.obj"/>
      </geometry>
    </visual>
    <collision>
      <geometry>
        <mesh filename="file:///home/shimanliang/ros2_ws/install/arx5_description/share/arx5_description/meshes/x5/link4.obj"/>
      </geometry>
    </collision>
  </link>
  <joint name="right_joint4" type="revolute">
    <origin xyz="0.245 0 -0.056"/>
    <parent link="right_link3"/>
    <child link="right_link4"/>
    <axis xyz="0 1 0"/>
    <limit effort="100" lower="-1.57" upper="1.57" velocity="5"/>
  </joint>
  <link name="right_link5">
    <inertial>
      <origin xyz="0.003612 -1.5455E-05 0.055214"/>
      <mass value="0.63488"/>
      <inertia ixx="0.00083" ixy="0.00000" ixz="0.00007" iyy="0.00082" iyz="0.00000" izz="0.00026"/>
    </inertial>
    <visual>
      <origin xyz="0.0037 0 0"/>
      <geometry>
        <mesh filename="file:///home/shimanliang/ros2_ws/install/arx5_description/share/arx5_description/meshes/x5/link5.obj"/>
      </geometry>
    </visual>
    <collision>
      <geometry>
        <mesh filename="file:///home/shimanliang/ros2_ws/install/arx5_description/share/arx5_description/meshes/x5/link5.obj"/>
      </geometry>
    </collision>
  </link>
  <joint name="right_joint5" type="revolute">
    <origin xyz="0.06775 0.0005 -0.0865"/>
    <parent link="right_link4"/>
    <child link="right_link5"/>
    <axis xyz="0 0 1"/>
    <limit effort="100" lower="-1.57" upper="1.57" velocity="5"/>
  </joint>
  <link name="right_link6">
    <inertial>
      <origin xyz="0.041697 2.4368E-05 0.00014464"/>
      <mass value="0.44089"/>
      <inertia ixx="0.00038" ixy="0.00000" ixz="0.00000" iyy="0.00028" iyz="0.00000" izz="0.00050"/>
    </inertial>
    <visual>
      <geometry>
        <mesh filename="file:///home/shimanliang/ros2_ws/install/arx5_description/share/arx5_description/meshes/x5/link6.obj"/>
      </geometry>
    </visual>
    <collision>
      <geometry>
        <mesh filename="file:///home/shimanliang/ros2_ws/install/arx5_description/share/arx5_description/meshes/x5/link6.obj"/>
      </geometry>
    </collision>
  </link>
  <joint name="right_joint6" type="revolute">
    <origin rpy="-3.1416 0 0" xyz="0.02895 0 0.0865"/>
    <parent link="right_link5"/>
    <child link="right_link6"/>
    <axis xyz="1 0 0"/>
    <limit effort="100" lower="-1.57" upper="1.57" velocity="5"/>
  </joint>
  <link name="right_link7">
    <inertial>
      <origin xyz="-0.00035522 -0.007827 -0.0029883"/>
      <mass value="0.064798"/>
      <inertia ixx="0.00002" ixy="0.00000" ixz="0.00000" iyy="0.00003" iyz="0.00000" izz="0.00003"/>
    </inertial>
    <visual>
      <geometry>
        <mesh filename="file:///home/shimanliang/ros2_ws/install/arx5_description/share/arx5_description/meshes/x5/link7.obj"/>
      </geometry>
    </visual>
    <collision>
      <geometry>
        <mesh filename="file:///home/shimanliang/ros2_ws/install/arx5_description/share/arx5_description/meshes/x5/link7.obj"/>
      </geometry>
    </collision>
  </link>
  <joint name="right_gripper_joint" type="prismatic">
    <origin xyz="0.08657 0.024896 -0.0002436"/>
    <parent link="right_link6"/>
    <child link="right_link7"/>
    <axis xyz="0 1 0"/>
    <limit effort="100" lower="0" upper="0.044" velocity="5"/>
  </joint>
  <link name="right_link8">
    <inertial>
      <origin xyz="-0.00035522 0.0078277 0.0024201"/>
      <mass value="0.064798"/>
      <inertia ixx="0.00002" ixy="0.00000" ixz="0.00000" iyy="0.00003" iyz="0.00000" izz="0.00003"/>
    </inertial>
    <visual>
      <geometry>
        <mesh filename="file:///home/shimanliang/ros2_ws/install/arx5_description/share/arx5_description/meshes/x5/link8.obj"/>
      </geometry>
    </visual>
    <collision>
      <geometry>
        <mesh filename="file:///home/shimanliang/ros2_ws/install/arx5_description/share/arx5_description/meshes/x5/link8.obj"/>
      </geometry>
    </collision>
  </link>
  <joint name="right_joint8" type="prismatic">
    <origin xyz="0.08657 -0.0249 -0.00024366"/>
    <parent link="right_link6"/>
    <child link="right_link8"/>
    <axis xyz="0 -1 0"/>
    <limit effort="100" lower="0" upper="0.044" velocity="5"/>
    <mimic joint="right_gripper_joint" multiplier="1" offset="0"/>
  </joint>
  <link name="right_gripper_center"/>
  <joint name="right_gripper_center_fixed" type="fixed">
    <parent link="right_link6"/>
    <child link="right_gripper_center"/>
    <origin xyz="0.145 0 0"/>
  </joint>
  <link name="right_left_pad"/>
  <joint name="right_left_pad_joint" type="fixed">
    <parent link="right_link7"/>
    <child link="right_left_pad"/>
    <origin xyz="0.05843 -0.0249 0"/>
  </joint>
  <link name="right_right_pad"/>
  <joint name="right_right_pad_joint" type="fixed">
    <parent link="right_link8"/>
    <child link="right_right_pad"/>
    <origin xyz="0.05843 0.0249 0"/>
  </joint>
  <link name="right_camera_support">
    <visual>
      <geometry>
        <mesh filename="file:///home/shimanliang/ros2_ws/install/arx5_description/share/arx5_description/meshes/camera_stand/stand_d405.obj"/>
      </geometry>
    </visual>
  </link>
  <joint name="right_camera_support_fixed" type="fixed">
    <parent link="right_link6"/>
    <child link="right_camera_support"/>
    <origin xyz="0.045 0 0.021"/>
  </joint>
  <link name="right_camera">
    <visual>
      <geometry>
        <mesh filename="file:///home/shimanliang/ros2_ws/install/sensor_models/share/sensor_models/meshes/d405/d405.obj"/>
      </geometry>
    </visual>
  </link>
  <joint name="right_camera_fixed" type="fixed">
    <origin rpy="0 0.523 0" xyz="0.0385 0 0.0475"/>
    <parent link="right_camera_support"/>
    <child link="right_camera"/>
  </joint>
  <joint name="arm_left_fixed" type="fixed">
    <parent link="lift_link"/>
    <child link="left_base_link"/>
    <origin rpy="0 0 0" xyz="0.059949 0.25 -0.036"/>
  </joint>
  <joint name="arm_right_fixed" type="fixed">
    <parent link="lift_link"/>
    <child link="right_base_link"/>
    <origin rpy="0 0 0" xyz="0.059949 -0.25 -0.036"/>
  </joint>
</robot>
