<?xml version="1.0" encoding="utf-8"?>
<!-- This URDF was automatically created by SolidWorks to URDF Exporter! Originally created by Stephen Brawner (brawner@gmail.com) 
     Commit Version: 1.6.0-4-g7f85cfe  Build Version: 1.6.7995.38578
     For more information, please see http://wiki.ros.org/sw_urdf_exporter -->
<robot
  name="arx_lift2s">
  <link
    name="base_link">
    <inertial>
      <origin
        xyz="-0.010039 0.0013761 0.04956"
        rpy="0 0 0" />
      <mass value="21.045" />
      <inertia
        ixx="1.70029164"
        ixy="-0.00073232"
        ixz="-0.03255532"
        iyy="1.70804910"
        iyz="-0.00688370"
        izz="0.97173287" />
    </inertial>
    <visual>
      <origin
        xyz="0 0 0"
        rpy="0 0 0" />
      <geometry>
        <mesh
          filename="package://arx_lift2s_description/meshes/base_link.glb" />
      </geometry>
    </visual>
    <collision>
      <origin
        xyz="0 0 0"
        rpy="0 0 0" />
      <geometry>
        <mesh
          filename="package://arx_lift2s_description/meshes/base_link.glb" />
      </geometry>
    </collision>
  </link>

  <link
    name="wheel_1">
    <inertial>
      <origin
        xyz="0.035966 2.6831E-06 8.693E-07"
        rpy="0 0 0" />
      <mass
        value="0.5746" />
      <inertia
        ixx="0.00142306"
        ixy="0.00000000"
        ixz="0.00000000"
        iyy="0.00084449"
        iyz="0.00000002"
        izz="0.00084474" />
    </inertial>
    <visual>
      <origin
        xyz="0 0 0"
        rpy="0 0 0" />
      <geometry>
        <mesh
          filename="package://arx_lift2s_description/meshes/wheel_1.glb" />
      </geometry>
    </visual>
    <collision>
      <origin
        xyz="0 0 0"
        rpy="0 0 0" />
      <geometry>
        <mesh
          filename="package://arx_lift2s_description/meshes/wheel_1.glb" />
      </geometry>
    </collision>
  </link>
  <joint
    name="wheel1_joint"
    type="continuous">
    <origin
      xyz="0.15361 0.29246 -0.093"
      rpy="0 0 1.0472" />
    <parent
      link="base_link" />
    <child
      link="wheel_1" />
    <axis
      xyz="1 0 0" />
    <limit
      effort="17"
      velocity="27" />
  </joint>
  <link
    name="wheel_2">
    <inertial>
      <origin
        xyz="0.035966 2.8161E-06 7.9768E-09"
        rpy="0 0 0" />
      <mass
        value="0.5746" />
      <inertia
        ixx="0.00142306"
        ixy="0.00000000"
        ixz="0.00000000"
        iyy="0.00084449"
        iyz="0.00000002"
        izz="0.00084474" />
    </inertial>
    <visual>
      <origin
        xyz="0 0 0"
        rpy="0 0 0" />
      <geometry>
        <mesh
          filename="package://arx_lift2s_description/meshes/wheel_2.glb" />
      </geometry>
    </visual>
    <collision>
      <origin
        xyz="0 0 0"
        rpy="0 0 0" />
      <geometry>
        <mesh
          filename="package://arx_lift2s_description/meshes/wheel_2.glb" />
      </geometry>
    </collision>
  </link>
  <joint
    name="wheel2_joint"
    type="continuous">
    <origin
      xyz="0.15361 -0.29245 -0.093"
      rpy="0 0 -1.0472" />
    <parent
      link="base_link" />
    <child
      link="wheel_2" />
    <axis
      xyz="1 0 0" />
    <limit
      effort="17"
      velocity="27" />
  </joint>
  <link
    name="wheel_3">
    <inertial>
      <origin
        xyz="-0.035971 2.8084E-06 -1.6209E-07"
        rpy="0 0 0" />
      <mass
        value="0.5746" />
      <inertia
        ixx="0.00142306"
        ixy="0.00000000"
        ixz="0.00000000"
        iyy="0.00084449"
        iyz="0.00000002"
        izz="0.00084474" />
    </inertial>
    <visual>
      <origin
        xyz="0 0 0"
        rpy="0 0 0" />
      <geometry>
        <mesh
          filename="package://arx_lift2s_description/meshes/wheel_3.glb" />
      </geometry>
    </visual>
    <collision>
      <origin
        xyz="0 0 0"
        rpy="0 0 0" />
      <geometry>
        <mesh
          filename="package://arx_lift2s_description/meshes/wheel_3.glb" />
      </geometry>
    </collision>
  </link>
  <joint
    name="wheel3_joint"
    type="continuous">
    <origin
      xyz="-0.35293 0 -0.093"
      rpy="0 0 0" />
    <parent
      link="base_link" />
    <child
      link="wheel_3" />
    <axis
      xyz="-1 0 0" />
    <limit
      effort="17"
      velocity="27" />
  </joint>

  <link
    name="lift_link">
    <inertial>
      <origin
        xyz="-0.053315 -0.00061422 -0.0086454"
        rpy="0 0 0" />
      <mass
        value="14.181" />
      <inertia
        ixx="0.32744849"
        ixy="-0.00306617"
        ixz="0.05920163"
        iyy="0.36541112"
        iyz="0.00117932"
        izz="0.49616592" />
    </inertial>
    <visual>
      <origin
        xyz="0 0 0"
        rpy="0 0 0" />
      <geometry>
        <mesh
          filename="package://arx_lift2s_description/meshes/body4.glb" />
      </geometry>
    </visual>
    <collision>
      <origin
        xyz="0 0 0"
        rpy="0 0 0" />
      <geometry>
        <mesh
          filename="package://arx_lift2s_description/meshes/body4.glb" />
      </geometry>
    </collision>
  </link>
  <joint
    name="lift_joint"
    type="prismatic">
    <origin
      xyz="0.094118 0.0010067 0.27"
      rpy="0 0 0" />
    <parent
      link="base_link" />
    <child
      link="lift_link" />
    <axis
      xyz="0 0 1" />
    <limit
      lower="0"
      upper="0.46"
      effort="400"
      velocity="0.15" />
  </joint>
  <link
    name="left_link1">
    <inertial>
      <origin
        xyz="0.0054231 -0.0080289 0.017086"
        rpy="0 0 0" />
      <mass
        value="0.066982" />
      <inertia
        ixx="0.00008086"
        ixy="0.00000207"
        ixz="-0.00000876"
        iyy="0.00003211"
        iyz="0.00000440"
        izz="0.00007702" />
    </inertial>
    <visual>
      <origin
        xyz="0 0 0"
        rpy="0 0 0" />
      <geometry>
        <mesh
          filename="package://arx_lift2s_description/meshes/left_link11.glb" />
      </geometry>
    </visual>
    <collision>
      <origin
        xyz="0 0 0"
        rpy="0 0 0" />
      <geometry>
        <mesh
          filename="package://arx_lift2s_description/meshes/left_link11.glb" />
      </geometry>
    </collision>
  </link>
  <joint
    name="left_joint1"
    type="revolute">
    <origin
      xyz="0.059949 0.25 0.0245"
      rpy="0 0 0" />
    <parent
      link="lift_link" />
    <child
      link="left_link1" />
    <axis
      xyz="0 0 1" />
    <limit
      lower="-2.094"
      upper="3.1416"
      effort="27"
      velocity="5.5" />
  </joint>
  <link
    name="left_link2">
    <inertial>
      <origin
        xyz="-0.13234 -0.0040166 0.00010941"
        rpy="0 0 0" />
      <mass
        value="1.1068" />
      <inertia
        ixx="0.00054299"
        ixy="-0.00000184"
        ixz="0.00003884"
        iyy="0.01652639"
        iyz="-0.00000035"
        izz="0.01654931" />
    </inertial>
    <visual>
      <origin
        xyz="0 0 0"
        rpy="0 0 0" />
      <geometry>
        <mesh
          filename="package://arx_lift2s_description/meshes/left_link12.glb" />
      </geometry>
    </visual>
    <collision>
      <origin
        xyz="0 0 0"
        rpy="0 0 0" />
      <geometry>
        <mesh
          filename="package://arx_lift2s_description/meshes/left_link12.glb" />
      </geometry>
    </collision>
  </link>
  <joint
    name="left_joint2"
    type="revolute">
    <origin
      xyz="0.02 0 0.04"
      rpy="0 0 0" />
    <parent
      link="left_link1" />
    <child
      link="left_link2" />
    <axis
      xyz="0 1 0" />
    <limit
      lower="0"
      upper="3.665"
      effort="27"
      velocity="5.5" />
  </joint>
  <link
    name="left_link3">
    <inertial>
      <origin
        xyz="0.18544 -0.00071369 0.051628"
        rpy="0 0 0" />
      <mass
        value="0.54316" />
      <inertia
        ixx="0.00036398"
        ixy="-0.00002814"
        ixz="-0.00039418"
        iyy="0.00422770"
        iyz="-0.00001179"
        izz="0.00419421" />
    </inertial>
    <visual>
      <origin
        xyz="0 0 0"
        rpy="0 0 0" />
      <geometry>
        <mesh
          filename="package://arx_lift2s_description/meshes/left_link13.glb" />
      </geometry>
    </visual>
    <collision>
      <origin
        xyz="0 0 0"
        rpy="0 0 0" />
      <geometry>
        <mesh
          filename="package://arx_lift2s_description/meshes/left_link13.glb" />
      </geometry>
    </collision>
  </link>
  <joint
    name="left_joint3"
    type="revolute">
    <origin
      xyz="-0.264 3E-05 0"
      rpy="0 0 0" />
    <parent
      link="left_link2" />
    <child
      link="left_link3" />
    <axis
      xyz="0 -1 0" />
    <limit
      lower="0"
      upper="3.24"
      effort="27"
      velocity="5.5" />
  </joint>
  <link
    name="left_link4">
    <inertial>
      <origin
        xyz="0.039966 -0.0043045 0.035006"
        rpy="0 0 0" />
      <mass
        value="0.11827" />
      <inertia
        ixx="0.00019329"
        ixy="-0.00001619"
        ixz="-0.00008654"
        iyy="0.00023401"
        iyz="-0.00001744"
        izz="0.00014391" />
    </inertial>
    <visual>
      <origin
        xyz="0 0 0"
        rpy="0 0 0" />
      <geometry>
        <mesh
          filename="package://arx_lift2s_description/meshes/left_link14.glb" />
      </geometry>
    </visual>
    <collision>
      <origin
        xyz="0 0 0"
        rpy="0 0 0" />
      <geometry>
        <mesh
          filename="package://arx_lift2s_description/meshes/left_link14.glb" />
      </geometry>
    </collision>
  </link>
  <joint
    name="left_joint4"
    type="revolute">
    <origin
      xyz="0.245 -3E-05 0.056"
      rpy="0 0 0" />
    <parent
      link="left_link3" />
    <child
      link="left_link4" />
    <axis
      xyz="0 -1 0" />
    <limit
      lower="-1.671"
      upper="1.671"
      effort="7"
      velocity="20" />
  </joint>
  <link
    name="left_link5">
    <inertial>
      <origin
        xyz="0.0029491 8.4086E-05 -0.054795"
        rpy="0 0 0" />
      <mass
        value="0.67398" />
      <inertia
        ixx="0.00092704"
        ixy="0.00000049"
        ixz="0.00004559"
        iyy="0.00091568"
        iyz="0.00000053"
        izz="0.00028327" />
    </inertial>
    <visual>
      <origin
        xyz="0 0 0"
        rpy="0 0 0" />
      <geometry>
        <mesh
          filename="package://arx_lift2s_description/meshes/left_link15.glb" />
      </geometry>
    </visual>
    <collision>
      <origin
        xyz="0 0 0"
        rpy="0 0 0" />
      <geometry>
        <mesh
          filename="package://arx_lift2s_description/meshes/left_link15.glb" />
      </geometry>
    </collision>
  </link>
  <joint
    name="left_joint5"
    type="revolute">
    <origin
      xyz="0.06775 0 0.0845"
      rpy="0 0 0" />
    <parent
      link="left_link4" />
    <child
      link="left_link5" />
    <axis
      xyz="0 0 -1" />
    <limit
      lower="-1.671"
      upper="1.671"
      effort="7"
      velocity="20" />
  </joint>
  <link
    name="left_link6">
    <inertial>
      <origin
        xyz="0.040212 3.4542E-05 -0.010225"
        rpy="0 0 0" />
      <mass
        value="0.34667" />
      <inertia
        ixx="0.00047210"
        ixy="-0.00000041"
        ixz="-0.00002976"
        iyy="0.00049011"
        iyz="-0.00003393"
        izz="0.00018496" />
    </inertial>
    <visual>
      <origin
        xyz="0 0 0"
        rpy="0 0 0" />
      <geometry>
        <mesh
          filename="package://arx_lift2s_description/meshes/left_link16.glb" />
      </geometry>
    </visual>
    <collision>
      <origin
        xyz="0 0 0"
        rpy="0 0 0" />
      <geometry>
        <mesh
          filename="package://arx_lift2s_description/meshes/left_link16.glb" />
      </geometry>
    </collision>
  </link>
  <joint
    name="left_joint6"
    type="revolute">
    <origin
      xyz="0.02895 0 -0.0845"
      rpy="0 0 0" />
    <parent
      link="left_link5" />
    <child
      link="left_link6" />
    <axis
      xyz="1 0 0" />
    <limit
      lower="-2.094"
      upper="2.094"
      effort="7"
      velocity="20" />
  </joint>
  <link
    name="left_link7">
    <inertial>
      <origin
        xyz="-0.0060354 -0.015602 0.013499"
        rpy="0 0 0" />
      <mass
        value="0.08924" />
      <inertia
        ixx="0.00009869"
        ixy="-0.00000394"
        ixz="0.00001011"
        iyy="0.00009021"
        iyz="0.00001113"
        izz="0.00006849" />
    </inertial>
    <visual>
      <origin
        xyz="0 0 0"
        rpy="0 0 0" />
      <geometry>
        <mesh
          filename="package://arx_lift2s_description/meshes/left_link17.glb" />
      </geometry>
    </visual>
    <collision>
      <origin
        xyz="0 0 0"
        rpy="0 0 0" />
      <geometry>
        <mesh
          filename="package://arx_lift2s_description/meshes/left_link17.glb" />
      </geometry>
    </collision>
  </link>
  <joint
    name="left_joint7"
    type="prismatic">
    <origin
      xyz="0.08397 0.02721 -0.0062702"
      rpy="0 0 0" />
    <parent
      link="left_link6" />
    <child
      link="left_link7" />
    <axis
      xyz="0 1 0" />
    <limit
      lower="0"
      upper="0.044"
      effort="300"
      velocity="0.053" />
  </joint>

  <link
    name="left_link8">
    <inertial>
      <origin
        xyz="-0.00581 0.015593 -0.012255"
        rpy="0 0 0" />
      <mass
        value="0.089402" />
      <inertia
        ixx="0.00007306"
        ixy="0.00000404"
        ixz="-0.00001526"
        iyy="0.00006428"
        iyz="0.00000327"
        izz="0.00006822" />
    </inertial>
    <visual>
      <origin
        xyz="0 0 0"
        rpy="0 0 0" />
      <geometry>
        <mesh
          filename="package://arx_lift2s_description/meshes/left_link18.glb" />
      </geometry>
    </visual>
    <collision>
      <origin
        xyz="0 0 0"
        rpy="0 0 0" />
      <geometry>
        <mesh
          filename="package://arx_lift2s_description/meshes/left_link18.glb" />
      </geometry>
    </collision>
  </link>
  <joint
    name="left_joint8"
    type="prismatic">
    <origin
      xyz="0.08397 -0.023638 -0.0062703"
      rpy="0 0 0" />
    <parent
      link="left_link6" />
    <child
      link="left_link8" />
    <axis
      xyz="0 -1 0" />
    <limit
      lower="0"
      upper="0.044"
      effort="300"
      velocity="0.053" />
  </joint>
  <link name="left_gripper_center"/>
  <joint name="left_gripper_center_joint" type="fixed">
      <origin xyz="0.14397 0 -0.0062703"/>
      <parent link="left_link6"/>
      <child link="left_gripper_center"/>
  </joint>

  <link
    name="right_link1">
    <inertial>
      <origin
        xyz="0.0054231 -0.0080289 0.017086"
        rpy="0 0 0" />
      <mass
        value="0.066982" />
      <inertia
        ixx="0.00008086"
        ixy="0.00000207"
        ixz="-0.00000876"
        iyy="0.00003211"
        iyz="0.00000440"
        izz="0.00007702" />
    </inertial>
    <visual>
      <origin
        xyz="0 0 0"
        rpy="0 0 0" />
      <geometry>
        <mesh
          filename="package://arx_lift2s_description/meshes/right_link21.glb" />
      </geometry>
    </visual>
    <collision>
      <origin
        xyz="0 0 0"
        rpy="0 0 0" />
      <geometry>
        <mesh
          filename="package://arx_lift2s_description/meshes/right_link21.glb" />
      </geometry>
    </collision>
  </link>
  <joint
    name="right_joint1"
    type="revolute">
    <origin
      xyz="0.059949 -0.25 0.0245"
      rpy="0 0 0" />
    <parent
      link="lift_link" />
    <child
      link="right_link1" />
    <axis
      xyz="0 0 1" />
    <limit
      lower="-2.094"
      upper="3.1416"
      effort="27"
      velocity="5.5" />
  </joint>
  <link
    name="right_link2">
    <inertial>
      <origin
        xyz="-0.13234 -0.0040166 0.00010941"
        rpy="0 0 0" />
      <mass
        value="1.1068" />
      <inertia
        ixx="0.00054299"
        ixy="-0.00000184"
        ixz="0.00003884"
        iyy="0.01652639"
        iyz="-0.00000035"
        izz="0.01654931" />
    </inertial>
    <visual>
      <origin
        xyz="0 0 0"
        rpy="0 0 0" />
      <geometry>
        <mesh
          filename="package://arx_lift2s_description/meshes/right_link22.glb" />
      </geometry>
    </visual>
    <collision>
      <origin
        xyz="0 0 0"
        rpy="0 0 0" />
      <geometry>
        <mesh
          filename="package://arx_lift2s_description/meshes/right_link22.glb" />
      </geometry>
    </collision>
  </link>
  <joint
    name="right_joint2"
    type="revolute">
    <origin
      xyz="0.02 0 0.04"
      rpy="0 0 0" />
    <parent
      link="right_link1" />
    <child
      link="right_link2" />
    <axis
      xyz="0 1 0" />
    <limit
      lower="0"
      upper="3.665"
      effort="27"
      velocity="5.5" />
  </joint>
  <link
    name="right_link3">
    <inertial>
      <origin
        xyz="0.18544 -0.00071369 0.051628"
        rpy="0 0 0" />
      <mass
        value="0.54316" />
      <inertia
        ixx="0.00036398"
        ixy="-0.00002814"
        ixz="-0.00039418"
        iyy="0.00422770"
        iyz="-0.00001179"
        izz="0.00419421" />
    </inertial>
    <visual>
      <origin
        xyz="0 0 0"
        rpy="0 0 0" />
      <geometry>
        <mesh
          filename="package://arx_lift2s_description/meshes/right_link23.glb" />
      </geometry>
    </visual>
    <collision>
      <origin
        xyz="0 0 0"
        rpy="0 0 0" />
      <geometry>
        <mesh
          filename="package://arx_lift2s_description/meshes/right_link23.glb" />
      </geometry>
    </collision>
  </link>
  <joint
    name="right_joint3"
    type="revolute">
    <origin
      xyz="-0.264 3E-05 0"
      rpy="0 0 0" />
    <parent
      link="right_link2" />
    <child
      link="right_link3" />
    <axis
      xyz="0 -1 0" />
    <limit
      lower="0"
      upper="3.24"
      effort="27"
      velocity="5.5" />
  </joint>
  <link
    name="right_link4">
    <inertial>
      <origin
        xyz="0.039966 -0.0043045 0.035006"
        rpy="0 0 0" />
      <mass
        value="0.11827" />
      <inertia
        ixx="0.00019329"
        ixy="-0.00001619"
        ixz="-0.00008654"
        iyy="0.00023401"
        iyz="-0.00001744"
        izz="0.00014391" />
    </inertial>
    <visual>
      <origin
        xyz="0 0 0"
        rpy="0 0 0" />
      <geometry>
        <mesh
          filename="package://arx_lift2s_description/meshes/right_link24.glb" />
      </geometry>
    </visual>
    <collision>
      <origin
        xyz="0 0 0"
        rpy="0 0 0" />
      <geometry>
        <mesh
          filename="package://arx_lift2s_description/meshes/right_link24.glb" />
      </geometry>
    </collision>
  </link>
  <joint
    name="right_joint4"
    type="revolute">
    <origin
      xyz="0.245 -3E-05 0.056"
      rpy="0 0 0" />
    <parent
      link="right_link3" />
    <child
      link="right_link4" />
    <axis
      xyz="0 -1 0" />
    <limit
      lower="-1.671"
      upper="1.671"
      effort="7"
      velocity="20" />
  </joint>
  <link
    name="right_link5">
    <inertial>
      <origin
        xyz="0.0029491 8.4086E-05 -0.054795"
        rpy="0 0 0" />
      <mass
        value="0.67398" />
      <inertia
        ixx="0.00092704"
        ixy="0.00000049"
        ixz="0.00004559"
        iyy="0.00091568"
        iyz="0.00000053"
        izz="0.00028327" />
    </inertial>
    <visual>
      <origin
        xyz="0 0 0"
        rpy="0 0 0" />
      <geometry>
        <mesh
          filename="package://arx_lift2s_description/meshes/right_link25.glb" />
      </geometry>
    </visual>
    <collision>
      <origin
        xyz="0 0 0"
        rpy="0 0 0" />
      <geometry>
        <mesh
          filename="package://arx_lift2s_description/meshes/right_link25.glb" />
      </geometry>
    </collision>
  </link>
  <joint
    name="right_joint5"
    type="revolute">
    <origin
      xyz="0.06775 0 0.0845"
      rpy="0 0 0" />
    <parent
      link="right_link4" />
    <child
      link="right_link5" />
    <axis
      xyz="0 0 -1" />
    <limit
      lower="-1.671"
      upper="1.671"
      effort="7"
      velocity="20" />
  </joint>
  <link
    name="right_link6">
    <inertial>
      <origin
        xyz="0.040212 3.4542E-05 -0.010225"
        rpy="0 0 0" />
      <mass
        value="0.34667" />
      <inertia
        ixx="0.00047210"
        ixy="-0.00000041"
        ixz="-0.00002976"
        iyy="0.00049011"
        iyz="-0.00003393"
        izz="0.00018496" />
    </inertial>
    <visual>
      <origin
        xyz="0 0 0"
        rpy="0 0 0" />
      <geometry>
        <mesh
          filename="package://arx_lift2s_description/meshes/right_link26.glb" />
      </geometry>
    </visual>
    <collision>
      <origin
        xyz="0 0 0"
        rpy="0 0 0" />
      <geometry>
        <mesh
          filename="package://arx_lift2s_description/meshes/right_link26.glb" />
      </geometry>
    </collision>
  </link>
  <joint
    name="right_joint6"
    type="revolute">
    <origin
      xyz="0.02895 0 -0.0845"
      rpy="0 0 0" />
    <parent
      link="right_link5" />
    <child
      link="right_link6" />
    <axis
      xyz="1 0 0" />
    <limit
      lower="-2.094"
      upper="2.094"
      effort="7"
      velocity="20" />
  </joint>
  <link
    name="right_link7">
    <inertial>
      <origin
        xyz="-0.0060354 -0.015602 0.013499"
        rpy="0 0 0" />
      <mass
        value="0.08924" />
      <inertia
        ixx="0.00009869"
        ixy="-0.00000394"
        ixz="0.00001011"
        iyy="0.00009021"
        iyz="0.00001113"
        izz="0.00006849" />
    </inertial>
    <visual>
      <origin
        xyz="0 0 0"
        rpy="0 0 0" />
      <geometry>
        <mesh
          filename="package://arx_lift2s_description/meshes/right_link27.glb" />
      </geometry>
    </visual>
    <collision>
      <origin
        xyz="0 0 0"
        rpy="0 0 0" />
      <geometry>
        <mesh
          filename="package://arx_lift2s_description/meshes/right_link27.glb" />
      </geometry>
    </collision>
  </link>
  <joint
    name="right_joint7"
    type="prismatic">
    <origin
      xyz="0.08397 0.02721 -0.0062702"
      rpy="0 0 0" />
    <parent
      link="right_link6" />
    <child
      link="right_link7" />
    <axis
      xyz="0 1 0" />
    <limit
      lower="0"
      upper="0.044"
      effort="300"
      velocity="0.053" />
  </joint>
  <link
    name="right_link8">
    <inertial>
      <origin
        xyz="-0.00581 0.015593 -0.012255"
        rpy="0 0 0" />
      <mass
        value="0.089402" />
      <inertia
        ixx="0.00007306"
        ixy="0.00000404"
        ixz="-0.00001526"
        iyy="0.00006428"
        iyz="0.00000327"
        izz="0.00006822" />
    </inertial>
    <visual>
      <origin
        xyz="0 0 0"
        rpy="0 0 0" />
      <geometry>
        <mesh
          filename="package://arx_lift2s_description/meshes/right_link28.glb" />
      </geometry>
    </visual>
    <collision>
      <origin
        xyz="0 0 0"
        rpy="0 0 0" />
      <geometry>
        <mesh
          filename="package://arx_lift2s_description/meshes/right_link28.glb" />
      </geometry>
    </collision>
  </link>
  <joint
    name="right_joint8"
    type="prismatic">
    <origin
      xyz="0.08397 -0.023638 -0.0062703"
      rpy="0 0 0" />
    <parent
      link="right_link6" />
    <child
      link="right_link8" />
    <axis
      xyz="0 -1 0" />
    <limit
      lower="0"
      upper="0.044"
      effort="300"
      velocity="0.053" />
  </joint>
  <link name="right_gripper_center"/>
  <joint name="right_gripper_center_joint" type="fixed">
        <origin xyz="0.14397 0 -0.0062703"/>
        <parent link="right_link6"/>
        <child link="right_gripper_center"/>
  </joint>
</robot>